## 1. 예외처리(exception handling)

### 1.1 프로그램 오류

컴파일 에러와 런타임 에러

Compile Error :  컴파일 시 발생하는 에러

Runtime Error : 실행 시에 발생하는 에러

Logical Error : 실행은 되지만, 의도와 다르게 동작하는 것

코드를 컴파일하면 컴파일러가 *.java에 대해 오타나 잘못된 구문, 자료형 체크 등의 기본적인 검사를 수행해 오류가 있는지를 알려준다. 컴파일러가 알려 준 에러를 모두 수정해서 컴파일을 성공적으로 마치면 클래스 파일이 생성되고 생성된 클래스 파일을 실행할 수 있게 된다.

런타임 에러를 방지하기 위해 프로그램의 실행도중 발생할 수 있는 모든 경우의 수를 고려해 이에 대비하는 게 필요하다. error와 exception이 있다.

error : 프로그램 코드에 의해 수습될 수 없는 심각한 오류

exception : 프로그램 코드에 의해 수숩될 수 있는 다소 미약한 오류

### 1.2 예외 클래스의 계층구조

![exception](./Exception.png)
       
Exception의 두 그룹

- Exception 클래스와 그 자손들
- RuntimeException 클래스와 그 자손들

RuntimeException은 주로 프로그래머의 실수에 의해 발생될 수 있는 예외들로,

ArrayIndexOutOfBounds, NullPointerException, ClassCastException, ArithmeticException(정수를 0으로 나누려고 하는 경우) 등이 있다.

### 1.3 예외처리하기 - try - catch문

예외처리(exception handling)

정의 - 프로그램 실행 시 발생할 수 있는 예외에 대비한 코드를 작성

목적 - 프로그램의 비정상 종료를 막고, 정상적인 실행상태를 유지

발생한 예외를 처리하지 못하면 프로그램은 비정상적으로 종료되며, 처리되지 못한 예외(uncaught exception)는 JVM의 '예외처리기(UncaughtExceptionHandler)'가 받아서 예외의 원인을 화면에 출력한다.

예외 처리를 위해 try - catch 문을 사용한다.

```java
try {
	// 예외가 발생할 가능성이 있는 문장을 작성
} catch (Exception e1) {
	// Exception1이 발생했을 경우, 이를 처리하기 위한 문장 작성
} catch (Exception e2) {
	// Exception2이 발생했을 경우, 이를 처리하기 위한 문장 작성
} catch (Exception e3) {
	// Exception3이 발생했을 경우, 이를 처리하기 위한 문장 작성
}
```

여러 예외 상황을 처리할 수 있게 catch에 작성할 수 있고 발생한 예외와 일치하는 한 개의 catch 블럭만 수행된다. 일치하는게 없으면 수행되지 않는다.

ExceptionEx1.java

```java
class Main{

  public static void main(String[] args){
    try {
      try {} catch (Exception e) {}
    } catch (Exception e) {
      try {} catch (Exception e) {} // 에러, 변수 e의 중복 선언
    }

      try {

    } catch (Exception e) {
      
    } 
  }

}
```

- 위의 예시처러 하나의 메서드 내에 여러 개의 try-catch 문이 사용될 수 있고, try 블럭 또는 catch 블럭에 또 다른 try-catch 문이 사용될 수 있다. catch 블럭 내에서도 예외가 발생할 수 있기 때문
- catch 블럭의 괄호 내에 선언된 변수는 catch 블럭 내에서만 유효하기 때문에, 위의 모든 catch 블럭에 참조변수 'e' 하나만 사용해도 된다.
- 하지만 catch 블럭 내에 또 하나의 try-catch 문이 포함된 경우 같은 이름의 참조변수를 사용할 수 없음

```java
class Main{

  public static void main(String[] args){

    int num = 100;
    int result = 0;

    for(int i=0; i <10; i++){
      result = num / (int) (Math.random() * 10);
      System.out.println(result);
    }

  }

}

// Exception in thread "main" java.lang.ArithmeticException: / by zero
//    at Main.main(Main.java:9)
```

위의 예제는 num에 저장된 값을 0~9 사이 임의의 정수로 나눈 결과를 출력하는 걸 10번 반복한다. 

random()을 사용했으므로 매번 결과가 다르나, 0으로 나누는 경우가 있어 Exception이 발생할 수 있다. ArithmeticException이 발생하는데 정수를 0으로 나누는게 금지되어 있어서 발생한다. 실수를 0으로 나누는 것은 문제가 되지 않으므로 예외 코드를 작성해보자

```java
class Main{

  public static void main(String[] args){

    int num = 100;
    int result = 0;

    for(int i=0; i <10; i++){
    
      try {
        result = num / (int) (Math.random() * 10);
        System.out.println(result);

      } catch (ArithmeticException e) {
        System.out.println("0");
      }
    }
  }

}
```

### 1.4 try-catch문에서의 흐름

예외가 발생하는 경우와 발생하지 않았을 때 흐름이(문장의 실행순서가) 다르다.

- Try 블럭 내에서 예외가 발생한 경우
    - 발생한 예외와 일치하는 catch 블럭이 있는지 확인
    - 일치하는 catch블럭을 찾게 되면, 그 catch 블럭 내의 문장들을 수행하고 전체 try-catch문을 빠져나가서 그 다음 문장을 계속해서 수행한다. 만일 일치하는 catch블럭을 찾지 못하면 예외는 처리되지 못한다.
- try 블럭 내에서 예외가 발생하지 않은 경우
    - catch 블럭을 거치지 않고 전체 try-catch문을 빠져나가서 수행을 계속한다.

예외가 없는 케이스

```java
class Main{

  public static void main(String[] args){

    System.out.println(1);
    System.out.println(2);

    try {
      System.out.println(3);
      System.out.println(4);
    } catch (Exception e) {
      System.out.println(5);
    
    }
    System.out.println(6);
  }

}

// 1 -> 2 -> 3 ->  4 -> 6
```

중간에 예외가 있는 케이스

```java
class Main{

  public static void main(String[] args){

    System.out.println(1);
    System.out.println(2);

    try {
      System.out.println(3);
      System.out.println(0/0); 
      System.out.println(4);
    } catch (ArithmeticException e) {
      System.out.println(5);
    
    }
    System.out.println(6);
  }

}

// 1 -> 2 -> 3 -> 5 -> 6
```

### 1.5 예외의 발생과 catch 블럭

catch 블럭은 괄호()와 블럭 {} 두 부분으로 나뉘는데 괄호 내에는 처리하고자 하는 예외와 같은 타입의 참조변수 하나를 선언해야 한다.

예외가 발생하면, 발생한 예외에 해당하는 클래스의 인스턴스가 만들어 진다. 

첫 번째 catch 블럭부터 차례로 내려가면서 catch 블럭의 괄호()내에 선언된 참조변수의 종류와 생성된 예외클래스의 인스턴스에 instanceof 연산자를 이용해 검사하게 되는데, 검사결과가 true인 catch 블럭을 만날 때까지 검사는 계속된다.

검사결과가 true인 catch 블럭을 찾으면 블럭에 있는 문장들을 모두 수행한 후 try-catch 문을 빠져나가고 예외는 처리되지만, 검사결과가 true인 catch 블럭이 하나도 없으면 예외는 처리되지 않는다. 

모든 예외 클래스는 Exception클래스의 자손이므로, catch 블럭의 괄호()에 Exception 클래스 타입의 참조변수를 선언해 놓으면 어떤 종류의 예외가 발생하더라도 이 catch 블럭에 의해서 처리된다.

```java
class Main{

  public static void main(String[] args){

    System.out.println(1);
    System.out.println(2);

    try {
      System.out.println(3);
      System.out.println(0/0); 
      System.out.println(4);
    } catch (Exception e) {
      System.out.println(5);
    
    }
    System.out.println(6);
  }

}
```

```java
class Main{

  public static void main(String[] args){
    System.out.println(1);			
		System.out.println(2);
		try {
			System.out.println(3);
			System.out.println(0/0);
			System.out.println(4); 		
		} catch (ArithmeticException ae)	{
			if (ae instanceof ArithmeticException) 
				System.out.println("true");	
			System.out.println("ArithmeticException");
		} catch (Exception e)	{
			System.out.println("Exception");
		}	
		System.out.println(6);
	}
}

// 1
// 2
// 3
// true
// ArithmeticException
// 6
```

에러에 해당하는 catch문을 찾으면 그것만 실행되고 다음거는 해당되도 실행되지 않음

### printStackTrace()와 getMessage()

예외가 발생했을 때 생성되는 예외 클래스의 인스턴스에는 발생한 예외에 대한 정보가 담겨져 있고 이걸 아래 2개의 메서드로 얻을 수 있다. 

printStackTract() - 예외 발생 당시의 호출스택에 있었던 메서드의 정보와 예외 메시지를 화면에 출력

getMessage() - 발생한 예외클래스의 인스턴스에 저장된 메시지를 얻을 수 있다.

```java
class Main{

  public static void main(String[] args){
    System.out.println(1);			
		System.out.println(2);
		try {
			System.out.println(3);
			System.out.println(0/0);
			System.out.println(4); 	 
		} catch (ArithmeticException ae)	{
			ae.printStackTrace();
			System.out.println("예외메시지 : " + ae.getMessage());
		}
		System.out.println(6);
	
	}
}

// 예외메시지 : / by zero
```

### 멀티 catch 블럭

JDK1.7부터 여러 catch 블럭을 '|' 기호를 이용해 하나의 catch 블럭으로 합칠 수 있게 되었으며, 이를 '멀티 catch 블럭'이라 한다. 아래의 코드에서 알 수 있듯이 '멀티 catch블럭'을 이용하면 중복된 코드를 줄일 수 있다. 그리고 '|' 기호로 연결할 수 있는 예외 클래스의 개수에는 제한이 없다.

```java
try {
	...
} catch (ExceptionA e) {
	e.printStackTrace();
} catch (ExceptionB e2) {
	e2.printStacktrace();
}
```

```java
try {
	...
} catch ( ExceptionA | ExceptionB e) {
	e.printStackTrace();
}
```

만약 멀티 catch 블럭의 '|' 기호로 연결된 예외 클래스가 조상과 자손의 관계에 있다면 컴파일 에러가 발생한다. 

왜냐하면 두 예외 클래스가 조상과 자손의 관계가 있다면, 그냥 다음과 같이 조상 클래스만 써주는 것과 같기 때문이다. 불필요한 코드는 제거하라는 의미에서 에러가 발생한다.

```java
catch ( 부모ExceptionA | 자식ExceptionB e) // error
```

그리고 멀티 catch는 하나의 catch 블럭으로 여러 에외를 처리하는 것이므로 발생한 예외를 멀티 catch 블럭으로 처리하게 되었을 때, **멀티 catch 블럭 내에서는 실제로 어떤 예외가 발생한 것인지 알 수가 없다**. 그래서 **참조변수 e로** 멀티 catch 블럭에 '|' 기호로 **연결된 예외 클래스들의 공통 분모인 조상 예외 클래스에 선언된 멤버만 사용할 수 있다**.

```java
try {
	...
} catch ( ExceptionA | ExceptionB e) {
		e.methodA(); // error, ExceptionA에 선언된 methodA()는 호출 불가
		
		if (e instanceof ExceptionA) {
				ExceptionA e1 = (ExceptionA) e;
				e1.methodA(); // OK, ExceptionA에 선언된 메서드 호출 가능
			} else { // if9e instanceof ExceptionB
				...
			}

			e.printStackTrace();
}
```

필요하다면 위와 같이 instanceof로 어떤 예외가 발생한 것인지 확인하고 개별적으로 처리할 수는 있다. 그러나 이렇게까지 해가면서 catch블럭을 합칠 일은 거의 없을 것이다. 

마지막으로 **멀티 catch 블럭에 선언된 참조변수 e는 상수이므로 값을 변경할 수 없다는 제약이** 있는데, 이것은 여러 catch 블럭이 하나의 참조변수를 공유하기 때문에 생기는 제약이다.

여러 catch 블럭을 멀티 catch 블럭으로 합치는 경우 대부분 코드를 간단히 하는 수준이므로 이런 제약에 대해 너무 고민하지 않아도 된다.

### 1.6 예외 발생시키기

throw를 이용해 프로그래머가 고의로 예외를 발생시킬 수 있다.

1. 연산자 new를 이용해서 발생시키려는 예외 클래스의 객체를 생성
2. 키워드 throw를 이용해 예외를 발생시킨다.

```java
class Main{

  public static void main(String[] args){
    try {
      Exception e = new Exception("고의로 발생시켰음");
      throw e;
      // throw new Exception("고의로 발생시켰음"); <- 이렇게 한 줄로 쓸 수도 있음
    } catch (Exception e) {
      System.out.println("error message : " + e.getMessage());
      e.printStackTrace();
    }
    System.out.println("프로그램 종료");

	}
}
```

Exception 인스턴스를 생성할 때 생성자에 String을 넣어주면, 이 String이 Exception 인스턴스에 메시지로 저장된다. 이 메시지는 getMessage()를 이용해 얻을 수 있다.

```java
class Main{

  public static void main(String[] args){
    throw new Exception("고의로 발생시켰음");
  
	}
}
```

위와 같이 작성하고 컴파일하면 컴파일 에러가 발생한다.

예외처리가 되어야 할 부분에 예외처리가 되어 있지 않다는 에러인데, 이렇게 'Exception클래스들'이 발생할 가능성이 있는 문장들에 대해 예외처리를 해주지 않으면 컴파일조차 되지 않는다.

```java
class Main{

  public static void main(String[] args){
    throw new RuntimeException();
  
	}
}
```

위의 경우 이전의 예제와 달리 컴파일이 되는데 이 예제는 명백히 RuntimeExcption을 발생시키는 코드를 갖고 있고, 이에 대해 예외처리를 하지 않았음에도 불구하고 성공적으로 컴파일이 된다. 

RuntimeException클래스와 그 자손 클래스에 해당하는 예외는 프로그래머의 실수에 의해 발생하는 것들이기 때문에 예외처리를 강제하지 않는다. 만일 RuntimeException 클래스들에 속한 예외가 발생할 가능성이 있는 코드에도 예외처리를 필수로 해야 한다면, 아래와 같이 참조 변수와 배열이 사용되는 모든 곳에 예외처리를 해주어야 할 것이다.

```java
try {
		int[] arr = new int[10];

		System.out.println(arr[0]);
} catch (ArrayIndexOutOfBoundsException ae) {
 ...
} catch (NullPointerException ne) {
	...
}
```

컴파일러가 예외처리를 확인하지 않는 RuntimeException 클래스들은 'unchecked예외'라고 부르고 예외처리를 확인하는 Exception클래스들은 'checked예외'로 부른다.

### 1.7 메서드에 예외 선언하기

예외를 처리하는 방법에 try-catch 문 외에 예외를 메서드에 선언하는 방법이 있다.

메서드에 예외를 선언하려면, 메서드의 선언부에 키워드 throws를 사용해서 메서드 내에서 발생할 수 있는 예외를 적어주기만 하면 된다. 그리고 예외가 여러 개일 경우에는 쉼표(,)로 구분한다.

```java
void method() throws Exception1, Exception2, ... ExceptionN {
	// 메서드 내용
}

// 아래처럼 Exception 클래스를 메서드에 선언하면, 
// 이 메서드는 모든 종류의 예외가 발생할 가능성이 있다는 뜻
void method() throws Exception {
	// 메서드 내용
}
```

오버라이딩할 때는 단순히 선언된 예외의 개수가 아니라 상속관계까지 고려해야 한다.

메서드의 선언부에 예외를 선언함으로써 메서드를 사용하려는 사람이 메서드의 선언부를 봤을 때, 이 메서드를 사용하기 위해 어떤 예외들이 처리되어져야 하는지 쉽게 알 수 있다.

**다른 언어와 달리 자바에서는 메서드 내에서 발생가능한 예외를 메서드의 선언부에 명시하여 이 메서드를 사용하는 쪽에서는 이에 대한 처리를 하도록 강요하기 때문**에, 더 견고한 프로그램 코드를 작성할 수 있다.

예를 들어, java.lang.Object 클래스의 wait 메서드에 대한 설명을 보면,

메서드의 선언부에 InterruptedException이 키워드 throws와 함께 적혀있다.

이 메서드에서는 InterruptedException이 발생할 수 있으니, 이 메서드를 호출하고자 하는 메서드에서는 InterruptedException을 처리해줘야 한다는 것이다.

InterruptedException을 타고 들어가면 InterruptedException가 Exception의 자손임을 알 수 있다. 따라서 InterruptedException은 반드시 처리해줘야 하는 예외임을 알 수 있다. 

그래서 wait 메서드의 선언부에 키워드 throws와 함께 선언되어져 있는 것이다.

Java API의 wait메서드 설명의 아래쪽에 있는 Throws:를 보면 wait메서드에서 발생할 수 있는 예외의 리스트와 언제 발생하는지에 대한 설명이 적혀 있다.

wait에서는 두 개의 예외가 적혀 있는데 다른 하나가 IllegalMonitorStateException 이다. 

이 에러는 RuntimeException 클래스의 자손이므로 IllegalMonitorStateException는 예외처리를 해주지 않아도 된다. 그래서 wait 메서드의 선언부에 IllegalMonitorStateException을 적지 않은 것이다. 

메서드에 예외를 선언할 때 일반적으로 RuntimeException 클래스들은 적지 않는다. 

이들은 메서드 선언부의 throws에 선언한다고 해서 문제가 되진 않으나 보통 반드시 처리해줘야 하는 예외들만 선언한다.

이처럼 Java API 문서를 통해 사용하고자 하는 메서드의 선언부와 "Throws"를 보고 이 메서드에서는 어떤 예외가 발생할 수 있으며 반드시 처리해줘야 하는 예외는 어떤 것들이 있는지 확인하는 것이 좋다.

사실 예외를 메서드의 throws에 명시하는 것은 예외를 처리하는 것이 아니라, 자신(예외가 발생할 가능성이 있는 메서드)을 호출한 메서드에게 예외를 전달해 예외처리를 떠맡기려는 것이다.

예외를 전달받은 메서드가 또다시 자신을 호출한 메서드에게 전달할 수 있으며, 이런 식으로 계속 호출스택에 있는 메서드들을 따라 전달되다가 제일 마지막에 있는 main 메서드에서도 예외가 처리되지 않으면 main 메서드마저 종료되어 프로그램이 전체가 종료된다.

```java
class Main{

  public static void main(String[] args) throws Exception {
    method1();	
  }	// main메서드의 끝

	static void method1() throws Exception {
		method2();
	}	// method1의 끝

	static void method2() throws Exception {
		throw new Exception();
	}	// method2의 끝
  
	
}
```

실행 결과

```java
Exception in thread "main" java.lang.Exception
    at Main.method2(Main.java:12)
    at Main.method1(Main.java:8)
    at Main.main(Main.java:4)
```

위의 실행결과를 보면, 프로그램 실행 도중 java.lang.Exception 이 발생해 비정상적으로 종료했다는 것과 예외가 발생했을 때 호출스택의 내용을 알 수 있다.

1. 예외가 발생했을 때, 모두 3개의 메서드가 호출 스택에 있었고
2. 예외가 발생한 곳은 제일 윗줄에 있는 method2()라는 것과
3. main메서드가 method1()을, 그리고 method1()은 method2()를 호출했다는 점을 알 수 있다.

위의 예제로 보면, method2()에서 'throw new Exception();' 문장에 의해 예외가 강제적으로 발생했으나 try-catch문으로 예외처리를 하지 않아 method2()는 종료되면서 예외를 자신을 호출한 method1()에게 넘겨준다. method1()에서도 역시 예외처리를 해주지 않았으므로 종료되면서 main메서드에게 예외를 넘겨준다. 

그러나 main 메서드에서도 예외처리가 안되어 있어 main 메서드가 종료되어 프로그램이 예외로 인해 비정상적으로 종료된 것이다. 

이처럼 예외가 발생한 메서드에서 예외처리를 하지 않고 자신을 호출한 메서드에게 예외를 넘겨줄 수 있지만, 이걸로 예외가 처리된 것은 아니고 예외를 단순히 전달만 하는 것이다.

결국 어느 한 곳에서라도 반드시 try-catch 문으로 예외처리를 해줘야 한다.

```java
class ExceptionEx13 {
	public static void main(String[] args) {
		method1(); 	  // 같은 클래스내의 static멤버이므로 객체생성없이 직접 호출가능.
  	}	// main메서드의 끝

	static void method1() {
		try {
		     throw new Exception();
		} catch (Exception e) {
			System.out.println("method1메서드에서 예외가 처리되었습니다.");
			e.printStackTrace();
		}
	}	// method1의 끝
}
```

```java
class Main{

  public static void main(String[] args) {
		try  {
				method1();		
		} catch (Exception e)	{
				System.out.println("main메서드에서 예외가 처리되었습니다.");
				e.printStackTrace();
		}
	}	// main메서드의 끝

	static void method1() throws Exception {
		throw new Exception();
	}	// method1()의 끝
  
	
}
```

두 예제 모두 main 메서드가 method1()을 호출하며 거기서 예외가 발생한다.

차이점은 예외처리 방식인데 

위의 경우 method1()에서 예외처리를 했고 아래는 method1()에서 예외를 선언해 자신을 호출하는 메서드인 main 메서드로 예외를 전달했으며, 호출한 메서드에서는 try-catch 문으로 예외처리를 했다.

예외가 발생한 메서드 내에서 처리되어지면 호출한 메서드는 예외가 발생한 사실조차 모르게 된다.

거기서 처리되지 않고 호출한 메서드로 넘겨주면, 호출한 메서드에서는 method1()을 호출한 라인에서 예외가 발생한 것으로 간주되어 이에 대한 처리를 하게 된다.

이처럼 예외가 발생한 메서드 'method1()'에서 예외를 처리할 수도 있고, 예외가 발생한 메서드를 호출한 'main메서드'에서 처리할 수도 있다. 또한 두 메서드가 예외처리를 분담할 수 도 있다.

```java
import java.io.*;

class Main{

 public static void main(String[] args) {
        // command line에서 입력받은 값을 이름으로 갖는 파일을 생성한다.
		File f = createFile(args[0]);	
		System.out.println( f.getName() + " 파일이 성공적으로 생성되었습니다.");
	} // main메서드의 끝

	static File createFile(String fileName) {
		try {
			if (fileName==null || fileName.equals(""))
				throw new Exception("파일이름이 유효하지 않습니다.");
		} catch (Exception e) {
             // fileName이 부적절한 경우, 파일 이름을 '제목없음.txt'로 한다.
			fileName = "제목없음.txt";	 
		} finally {
			File f = new File(fileName); // File클래스의 객체를 만든다.
			createNewFile(f);		     // 생성된 객체를 이용해서 파일을 생성한다.
			return f;
		}
	}	// createFile메서드의 끝

	static void createNewFile(File f) {
		try {
			f.createNewFile();		// 파일을 생성한다.
		} catch(Exception e){ }
	}	// createNewFile메서드의 끝
}
```

이 예제는 예외가 발생한 메서드에서 직접 예외를 처리하도록 되어 있다. createFile메서드를 호출한 main메서드에서는 예외가 발생한 사실을 알지 못한다. 적절하지 못한 파일이름이 입력되면, 예외를 발생시키고, catch 블럭에서, 파일이름을 "제목없음.txt"로 설정해서 파일을 생성한다.

그리고 finally 블럭에서는 예외의 발생여부에 관계없이 파일을 생성하는 일을 한다.

```java
import java.io.*;

class Main{

 public static void main(String[] args) 
	{
		try {
			File f = createFile(args[0]);
			System.out.println( f.getName()+"파일이 성공적으로 생성되었습니다.");
		} catch (Exception e) {
			System.out.println(e.getMessage()+" 다시 입력해 주시기 바랍니다.");
		}
	}	// main메서드의 끝

	static File createFile(String fileName) throws Exception {
		if (fileName==null || fileName.equals(""))
			throw new Exception("파일이름이 유효하지 않습니다.");
		File f = new File(fileName);		//  File클래스의 객체를 만든다.
        // File객체의 createNewFile메서드를 이용해서 실제 파일을 생성한다.
		f.createNewFile();
		return f;		// 생성된 객체의 참조를 반환한다.
	}	// createFile메서드의 끝
}
```

이 예제에서는 예외가 발생한 createFile에서 잘못 입력된 파일이름을 임의로 처리하지 않고, 호출한 main 메서드에게 예외가 발생했음을 알려서 파일이름을 다시 입력 받도록 했다.

createFile메서드에 예외를 선언했기 때문에, File 클래스의 createNewFile()에 대한 예외 처리를 하지 않아도 되므로 createNewFile(File file) 메서드를 굳이 만들지 않았다.

차이점은 예외 처리 방법인데, 위위의 예제는 예외가 발생한 createFile 메서드 자체 내에서 처리를 하고, 위의 예제는 createFile 메서드를 호출한 main 메서드에서 처리한다.

이렇게 예외가 발생한 메서드 내에서 자체적으로 처리해도 되는 것은 메서드 내에서 try-catch 문을 사용해서 처리하고, 두 번째 예제처럼 메서드에 호출 시 넘겨받아야 할 값을 다시 받아야 하는 경우(메서드 내에서 자체적으로 해결이 안되는 경우)에는 예외를 메서드에 선언해서, 호출한 메서드에서 처리해야 한다.

### 1.8 finally 블럭

finally 블럭은 예외의 발생여부에 상관없이 실행되어야 할 코드를 포함시킬 목적으로 사용된다. try-catch 문의 끝에 선택적으로 덧붙여 사용할 수 있으며, try-catch-finally의 순서로 구성된다.

```java
try {
	// 예외가 발생할 가능성이 있는 문장
} catch ( Exception e1) {
	// 예외처리를 위한 문장
} finally {
	// 예외 발생 여부에 관계없이 항상 수행되어야 하는 문장을 넣음
	// finally블럭은 try-catch문의 맨 마지막에 위치해야한다.
}
```

예외가 발생한 경우에는'try → catch → 'fianlly' 순으로 실행되고 예외가 발생하지 않으면 try → finally 순으로 실행된다.

```java
class Main{

 public static void main(String args[]) {
		try {
			startInstall();		// 프로그램 설치에 필요한 준비를 한다.
			copyFiles();		// 파일들을 복사한다. 
			deleteTempFiles();	// 프로그램 설치에 사용된 임시파일들을 삭제한다.
		} catch (Exception e) {
			e.printStackTrace();
		    	deleteTempFiles();   // 프로그램 설치에 사용된 임시파일들을 삭제한다.
		} // try-catch의 끝
	} // main의 끝

   static void startInstall() { 
        /* 프로그램 설치에 필요한 준비를 하는 코드를 적는다.*/ 
   }
   static void copyFiles() { /* 파일들을 복사하는 코드를 적는다. */ }
   static void deleteTempFiles() { /* 임시파일들을 삭제하는 코드를 적는다.*/ }
}
```

위 예제에서는 프로그램 설치를 위한 준비를 하고 파일을 복사하고 설치가 완료되면 프로그램을 설치하는데 사용된 임시파일들을 삭제하는 순서로 진행된다.

프로그램 설치과정 중에 예외가 발생하더라도, 설치에 사용된 임시파일들이 삭제되도록 catch 블럭에 deleteTempFiles()메서드를 넣었다.

결국 try블럭의 문장을 수행하는 동안에(프로그램 설치하는 과정에), 예외의 발생여부에 관계없이 deleteTempFiles() 메서드는 실행되어야 한다.

이럴 때 finally블럭을 사용하면 좋다. 

```java
class FinallyTest2 {
	public static void main(String args[]) {
		try {
			startInstall();		// 프로그램 설치에 필요한 준비를 한다.
			copyFiles();		// 파일들을 복사한다. 
		} catch (Exception e)	{
			e.printStackTrace();
		} finally {
			deleteTempFiles();	// 프로그램 설치에 사용된 임시파일들을 삭제한다.
		} // try-catch의 끝
	}	// main의 끝

   static void startInstall() {
        /* 프로그램 설치에 필요한 준비를 하는 코드를 적는다.*/ 
   }
   static void copyFiles() { /* 파일들을 복사하는 코드를 적는다. */ }
   static void deleteTempFiles() { /* 임시파일들을 삭제하는 코드를 적는다.*/}
```

```java
class FinallyTest3 {
	public static void main(String args[]) {
		// method1()은 static메서드이므로 인스턴스 생성없이 직접 호출이 가능하다.
		FinallyTest3.method1();		
        System.out.println("method1()의 수행을 마치고 main메서드로 돌아왔습니다.");
	}	// main메서드의 끝

	static void method1() {
		try {
			System.out.println("method1()이 호출되었습니다.");
			return;		// 현재 실행 중인 메서드를 종료한다.
		}	catch (Exception e)	{
			e.printStackTrace();
		} finally {
			System.out.println("method1()의 finally블럭이 실행되었습니다.");
		}
	}	// method1메서드의 끝
}
```

try 구문에서 return 문이 실행되는 경우에도 finally 블럭의 문장들이 먼저 실행된 후에, 현재 실행 중인 메서드를 종료한다. 마찬가지로 catch 블럭의 문장 수행 중에 return문을 만나도 finally 블럭의 문장들은 수행된다.

    
	
### 1.9 자동 자원 반환 -try-with-resource문

JDK1.7부터 try-with-resource문이라는 try-catch의 변형이 새로 추가되었다.

이 구문은 15장의 입출력(I/O)과 관련된 클래스 사용에 유용하다.

주로 입출력에 사용되는 클래스 중에서는 사용한 후에 꼭 닫아줘야 하는 것들이 있다.

그래야 사용했던 자원들이 반환되기 때문이다.

```java
try {
	fis = new FileInputStream("score.dat");
	dis = new DataInputStream(fis);

} catch ( IOException ie ) {
		ie.printStackTrace();
} finally {
		dis.close(); // 작업 중 예외가 발생하더라도 dis는 닫게 finally 블록에 넣음
}
```

위의 코드는 DataInputStream을 사용해 파일로부터 데이터를 읽는 코드인데, 데이터를 읽는 도중에 예외가 발생하더라도 DataInputStream이 닫히도록 finally 블럭 안에 close()를 넣었다. 

문제는 clsoe()가 예외를 발생시킬 수 있다는 점이다. 

그래서 위의 코드는 아래처럼 작성되어야 한다.

```java
try {
	fis = new FileInputStream("score.dat");
	dis = new DataInputStream(fis);

} catch ( IOException ie ) {
		ie.printStackTrace();
} finally {
		try {
				if(dis! = null)
						dis.close();
		} catch (IOException ie) {
		ie.printStackTrace();
	}
}
```

finally 안에도 try-catch 문을 추가해 close()에서 발생할 수 있는 예외를 처리한다. 코드가 복잡해져서 가독성이 좋지 않아졌다. 더 나쁜 것은 try 블럭과 finally 블럭 모두 예외가 발생하면 try 블럭의 예외가 무시된다는 점이다.

이런 점을 개선하기 위해 등장한게 try-with-resource문이다. 위의 코드를 고쳐보면 아래와 같다.

```java
try {FileInputStream fis = new FileInputStream("score.dat");
		DataInputStream dis = new DataInputStream(fis)) {

	while (true) {
		score = dis.readInt();
		System.out.println(score);
		sum += score;
	}
} catch ( EOFExceptione ) {
		System.out.println("점수의 총합은 " + sum + "입니다.");
} catch (IOException ie) {
		ie.printStackTrace();
}
```

try-with-resource문의 괄호 안에 객체를 생성하는 문장을 넣으면, 이 객체는 따로 close()를 호출하지 않아도 try 블럭을 벗어나는 순간 자동적으로 close()가 호출된다. 그 다음에 catch 블럭 또는 finally 블럭이 수행된다.

이처럼 try-with-resource문에 의해 자동으로 객체의 close()가 호출될 수 있으려면 클랫가 AutoCloseable이라는 인터페이스를 구현한 것이어야만 한다.

```java
public interface AutoCloseable {
		void close() throws Exception;
}
```

위의 인터페이스는 각 클래스에서 적절히 자원 반환작업을 도와주게 구현되어 있다. 

그런데 위의 코드를 잘 보면 clsoe()도 Exception을 발생시킬 수 있다. 만일 자동 호출된 close()에서 예외가 발생하면 어떻게 될까?

```java
class Main{

 public static void main(String args[]) {

		try (CloseableResource cr = new CloseableResource()) {
			cr.exceptionWork(false); // 예외가 발생하지 않는다.
 		} catch(WorkException e) {
			e.printStackTrace();
		} catch(CloseException e) {
			e.printStackTrace();
		}
		System.out.println();
	
		try (CloseableResource cr = new CloseableResource()) {
			cr.exceptionWork(true); // 예외가 발생한다.
 		} catch(WorkException e) {
			e.printStackTrace();
		} catch(CloseException e) {
			e.printStackTrace();
		}	
	} // main의 끝
}

class CloseableResource implements AutoCloseable {
	public void exceptionWork(boolean exception) throws WorkException {
		System.out.println("exceptionWork("+exception+")가 호출됨");

		if(exception)
			throw new WorkException("WorkException발생!!!");
	}

	public void close() throws CloseException {
		System.out.println("close()가 호출됨");
		throw new CloseException("CloseException발생!!!");
	}
}

class WorkException extends Exception {
	WorkException(String msg) { super(msg); }
}

class CloseException extends Exception {
	CloseException(String msg) { super(msg); }
}

exceptionWork(false)가 호출됨
close()가 호출됨
CloseException: CloseException발생!!!
    at CloseableResource.close(Main.java:36)
    at Main.main(Main.java:9)

exceptionWork(true)가 호출됨
close()가 호출됨
WorkException: WorkException발생!!!
    at CloseableResource.exceptionWork(Main.java:31)
    at Main.main(Main.java:17)
    Suppressed: CloseException: CloseException발생!!!
        at CloseableResource.close(Main.java:36)
        at Main.main(Main.java:16)
```

main 메서드에 두 개의 try-catch 문이 있는데, 첫 번째 것은 close()에서만 예외를 발생시키고, 두 번째 것은 exceptionWork()와 close()에서 모두 예외를 발생시킨다.

첫 번째는 일반적인 예외가 발생했을 때와 같은 형태로 출력되었지만, 두 번째는 출력형태가 다르다. 

먼저 exceptionWork()에서 발생한 예외에 대한 내용이 출력되고, close()에서 발생한 예외는 '억제된(suppressed)'이라는 의미의 머림라과 함께 출력되었다. 

두 예외가 동시에 발생할 수는 없기 때문에, 실제 발생한 예외를 WorkException으로 하고, CloseException은 억제된 예외로 다룬다. 억제된 예외에 대한 정보는 실제로 발생한 예외인 WorkException에 저장된다.

Throwable에는 억제된 예외와 관련된 다음과 같은 메서드가 정의되어 있다.

```java
void addSuppressed(Throwable exception) 억제된 에외를 추가
Throwable[] getSuppressed() 억제된 예외(배열)를 반환
```

만일 기존의 try-catch문을 사용했다면, 먼저 발생한 WorkException은 무시되고, 마지막으로 발생한 CloseException에 대한 내용만 출력되었을 것이다.

### 1.10 사용자정의 예외 만들기

가능하면 기존의 예외 클래스를 활용하되 새로운 예외 클래스를 만들 수도 있다.

```java
class MyException extends Exception {
	MyException(String msg) // 문자열을 매개변수로 받는 생성자
 { super(msg); } // 조상인 Exception 클래스의 생성자를 호출한다.
}
```

Exception 클래스로부터 상속받아서 MyException 클래스를 만들었다. 필요하다면, 멤버변수나 메서드를 추가할 수 있다. Exception 클래스는 생성 시에 String값을 받아서 메시지로 저장할 수 있다.

```java
class MyException extends Exception {
	private final int ERR_CODE; // 생성자를 통해 초기화

	MyException(String msg, int errCode ) { // 문자열을 매개변수로 받는 생성자
	  super(msg); 
		ERR_CODE = errCode;
	} // 조상인 Exception 클래스의 생성자를 호출한다.

	MyException(String msg) { 
	  this(msg, 100);  // ERR_CODE를 100(기본값)으로 초기화
	} 
	
	public int getErrCode() {  // 에러 코드를 얻을 수 있는 메서드 추가
			return ERR_CODE; // 이 메서드는 주로 getMessage() 와 함께 사용될 것
	}

}
```

이전의 코드를 개선해 메시지 뿐만 아니라 에러코드 값도 저장할 수 있도록 ERR_CODE와 getErrCode()를 MyException클래스의 멤버로 추가했다.

이렇게 함으로써 MyException이 발생했을 때, catch 블럭에서 getMessage()와 getErrCode()를 사용해서 에러코드와 메시지를 모두 얻을 수 있을 것이다.

기존의 예외 클래스는 주로 Exception을 상속받아서 'checked예외'로 작성하는 경우가 많았으나, 요즘은 예외처리를 선택적으로 할 수 있도록 RuntimeException을 상속받아서 작성하는 쪽으로 바뀌어가고 있다. 'checked 예외'는 반드시 예외처리를 해줘야 하기 때문에 예외처리가 불필요한 경우에도 try-catch문을 넣어서 코드가 복잡하기 때문이다.

예외처리를 강제하도록 한 이유는 프로그래밍 경험이 적은 사람들도 보다 견고한 프로그램 작성을 하게끔 유도하는 것인데 현재는 프로그래밍 환경이 바뀌어 필수로 처리해야할 것 같았던 예외들이 선택적으로 처리해도 되는 상황으로 바뀌는 경우가 종종 있다.

그래서 필요에 따라 예외처리의 여부를 선택할 수 있는 'unchecked예외'가 강제적인 'checked예외'보다 환영받고 있다.

```java
class Main{

 public static void main(String args[]) {
		try {
			startInstall();		// 프로그램 설치에 필요한 준비를 한다.
			copyFiles();			// 파일들을 복사한다. 
		} catch (SpaceException e)	{
			System.out.println("에러 메시지 : " + e.getMessage());
			e.printStackTrace();
			System.out.println("공간을 확보한 후에 다시 설치하시기 바랍니다.");
		} catch (MemoryException me)	{
			System.out.println("에러 메시지 : " + me.getMessage());
			me.printStackTrace();
			System.gc();		//  Garbage Collection을 수행하여 메모리를 늘려준다.
			System.out.println("다시 설치를 시도하세요.");
		} finally {
			deleteTempFiles();	// 프로그램 설치에 사용된 임시파일들을 삭제한다.
		} // try의 끝
	} // main의 끝

   static void startInstall() throws SpaceException, MemoryException { 
		if(!enoughSpace()) 		// 충분한 설치 공간이 없으면...
			throw new SpaceException("설치할 공간이 부족합니다.");
		if (!enoughMemory())		// 충분한 메모리가 없으면...
			throw new MemoryException("메모리가 부족합니다.");
   } // startInstall메서드의 끝

   static void copyFiles() { /* 파일들을 복사하는 코드를 적는다. */ }
   static void deleteTempFiles() { /* 임시파일들을 삭제하는 코드를 적는다.*/}
   
   static boolean enoughSpace()   {
		// 설치하는데 필요한 공간이 있는지 확인하는 코드를 적는다.
		return false;
   }
   static boolean enoughMemory() {
		// 설치하는데 필요한 메모리공간이 있는지 확인하는 코드를 적는다.
		return true;
   }
} // ExceptionTest클래스의 끝

class SpaceException extends Exception {
	SpaceException(String msg) {
	   super(msg);	
   }
} 

class MemoryException extends Exception {
	MemoryException(String msg) {
	   super(msg);	
   }
}

에러 메시지 : 설치할 공간이 부족합니다.
SpaceException: 설치할 공간이 부족합니다.
    at Main.startInstall(Main.java:23)
    at Main.main(Main.java:5)
공간을 확보한 후에 다시 설치하시기 바랍니다.
```

MemoryException, SpaceException 이 두개의 사용자정의 예외 클래스르 새로 만들어 사용햇다.

후자는 프로그램을 설치하려는 곳에 충분한 공간이 없을 경우 발생하도록 했으며, 전자는 설치작업을 수행하는데 메모리가 충분히 확보되지 않는 경우 발생하도록 했다.

이 두 예외는 startInstall()을 수행하는 동안 발생할 수 있으며, enoughSpace()와 enoughMemeory()의 실행결과에 따라서 발생하는 예외의 종류가 달라지도록 했다.

### 1.11 예외 되던지기(exception re-throwing)

한 메서드에서 발생할 수 있는 예외가 여럿인 경우, 몇 개는 try-catch문을 통해 메서드 내에서 자체적으로 처리하고, 그 나머지는 선언부에 지정해 호출한 메서드에서 처리하도록 함으로써, 양쪽에서 나눠 처리되도록 할 수 있다.

그리고 심지어는 단 하나의 예외에 대해서도 예외가 발생한 메서드와 호출한 메서드, 양쪽에서 처리하도록 할 수 있다.

예외를 처리한 후 인위적으로 다시 발생시키는 방법을 통해서 가능한데 이걸 '예외 되던지기(exception re-throwing)'라고 한다.

먼저 예외가 발생할 가능성이 있는 메서드에서 try-catch문을 사용해 예외를 처리해주고 catch문에서 필요한 작업을 행한 후 throw문을 사용해서 예외를 발생시킨다. 

다시 발생한 예외는 이 메서드를 호출한 메서드에게 전달되고 호출한 메서드의 try-catch문에서 예외를 또다시 처리한다. 

이 방법은 하나의 예외에 대해서 예외가 발생한 메서드와 이를 호출한 메서드 양쪽 모두에서 처리해줘야 할 작업이 있을 때 사용된다. 이 때 주의할 점은 예외가 발생할 메서드에서는 try-catch문을 사용해서 예외처리를 해줌과 동시에 메서드의 선언부에 발생할 예외를 throws에 지정해줘야 한다는 것이다.

```java
class Main{

 public static void main(String[] args) 
	{
		try  {
			method1();		
		} catch (Exception e)	{
			System.out.println("main메서드에서 예외가 처리되었습니다.");
		}
	}	// main메서드의 끝

	static void method1() throws Exception {
		try {
			throw new Exception();
		} catch (Exception e) {
			System.out.println("method1메서드에서 예외가 처리되었습니다.");
			throw e;			// 다시 예외를 발생시킨다.
		}
	}	// method1메서드의 끝
}

method1메서드에서 예외가 처리되었습니다.
main메서드에서 예외가 처리되었습니다.
```

결과에서 알 수 있듯이 method1()과 main 메서드 양쪽의 catch 블럭이 모두 수행되었음을 알 수 있다. method1() catch 블럭에서 예외를 처리하고도 throw문을 통해 다시 예외를 발생시켰다. 

그리고 이 예외를 main메서드에서 한 번 더 처리했다.

반환값이 있는 return문의 경우, catch블럭에도 return문이 있어야 한다. 예외가 발생했을 경우에도 값을 반환해야 하기 때문이다.

```java
	static int method1() {
		try {
			System.out.println("method1메서드 호출");
			return 0; // 현재 실행 중인 메서드 종료
		} catch (Exception e) {
			e.printStackTrace();
			return 1; // catch 블럭 내에도 return 문 필요
		} finally {
			System.out.println("method1메서드의 fianlly 블록 실행");
		}
	}	// method1메서드의 끝
```

또는 catch 블럭에서 예외 되던지기를 해서 호출한 메서드로 예외를 전달하면, return문이 없어도 된다. 그래서 검증에서도 assert문 대신 AssertError를 생성해서 던진다.

(assert문은 검증(assertion)을 수행하기 위한 문장으로 이 책에서는 다루지 않는다.)

```java
	static int method1() throws Exception {
		try {
			System.out.println("method1메서드 호출");
			return 0; // 현재 실행 중인 메서드 종료
		} catch (Exception e) {
			e.printStackTrace();
			return 1; // catch 블럭 내에도 return 문 필요
			throw new Exception(); // return문 대신 예외를 호출한 메서드로 전달
		} finally {
			System.out.println("method1메서드의 fianlly 블록 실행");
		}
	}	// method1메서드의 끝
```

finally블럭 내에서도 return문을 사용할 수 있으며 try 블럭인 catch 블럭 다음에 수행된다. 최종적으로 fianlly 블럭 내의 return문의 값이 반환된다.

### 1.12 연결된 예외(chained exception)

한 예외가 다른 예외를 발생시킬 수도 있다.

예를 들어, 예외 A가 예외 B를 발생시켰다면, A를 B의 '원인 예외(cause exception)'라고 한다.

```java
	try {
			startInstall();		// SpaceException 발생
			copyFiles();		
		} catch (SpaceException e)	{
			InstallException ie = new Installexception("설치중 예외발생"); // 예외 생성
			ie.initCause(e); // InstallException의 원인 예외를 SpaceException으로 지정
			throw ie; // InstallException을 발생시킴
		} catch (MemoryException me)	{
			...
```

먼저 InstallException을 생성한 후에, initCause()로 SpaceException을 InstallException의 원인 예외로 등록한다. 그리고 'throw'로 이 예외를 던진다.

initCause()는 Exception클래스의 조상인 Throwable클래스에 정의되어 있기 때문에 모든 예외에서 사용가능하다. 

```java
Throwable initCause(Throwable cause) // 지정한 예외를 원인 예외로 등록
Throwable getCause() // 원인 예외를 반환
```

발생한 예외를 그냥 처리하면 될 텐데, 원인 예외로 등록해서 다시 예외를 발생시키는지 궁금할 것이다. 그 이유는 여러가지 예외를 하나의 큰 분류의 예외로 묶어서 다루기 위해서다.

그렇다고 아래와 같이 InstallException은 SpaceException과 MemoryException의 조상으로 해서 catch 블럭을 작성하면, 실제로 발생한 예외가 어떤 건지 알 수 없다는 문제가 생긴다.

그리고 SpaceException과 MemeoryException의 상속관계를 변경해야 한다는 것도 부담이다.

```java
try {
		startInstall();  // SpaceException 발생
		copyFiles();
} catch ( InstallException e) { // InstallException은
			e.printStackTrace();// SpaceException과 MemoryException의 조상
}
```

그래서 생각한 것이 예외가 원인 예외를 포함할 수 있게 한 거다. 이렇게 하면 두 예외는 상속관계까 아니어도 상관 없다.

```java
public class Throwable implements Serialzable {
			...
	private Throwable cause = this; // 객체 자신을(this) 원인 예외로 등록
			...
}
```

또 다른 이유는 checked예외를 unchecked예외로 바꿀 수 있도록 하기 위함이다.

checked예외가 발생해도 예외를 처리할 수 없는 상황이 하나둘 발생하기 시작했는데 이럴 때 할 수 있는 일이 그냥 try-catch문을 추가하는 것 뿐이었다. 

이제는 checked예외를 unchecked예외로 바꾸면 예외처리가 선택적이 되므로 억지로 예외처리를 하지 않아도 된다.

```java
 static void startInstall() throws SpaceException, MemoryException { 
		if(!enoughSpace()) 		// 충분한 설치 공간이 없으면...
			throw new SpaceException("설치할 공간이 부족합니다.");
		if (!enoughMemory())		// 충분한 메모리가 없으면...
			***throw new MemoryException("메모리가 부족합니다.");***
   } 

```

```java
 static void startInstall() throws SpaceException, MemoryException { 
		if(!enoughSpace()) 		// 충분한 설치 공간이 없으면...
			throw new SpaceException("설치할 공간이 부족합니다.");
		if (!enoughMemory())		// 충분한 메모리가 없으면...
			***throw new RuntimeException( new MemoryException("메모리가 부족합니다."));***
   } 

```

MemoryException은 Exception의 자손이므로 반드시 예외를 처리해야 하는데 이 예외를 RuntimeException으로 감싸서 unchecked 예외가 되었다. 그래서 더 이상 startInstall()의 선언부에 MemoryException을 선언하지 않아도 된다. 참고로 위의 코드에서는 initCause()대신 RuntimeException의 생성자를 사용했다.

```java
RuntimeException(Throwable cause); // 원인 예외를 등록하는 생성자
```

마지막 예제로 지금까지 학습한 것을 확인하자

```java
class Main{
public static void main(String args[]) {
		try {
			install();
		} catch(InstallException e) {
			e.printStackTrace();
		} catch(Exception e) {
			e.printStackTrace();		
		}
	} // main의 끝

	static void install() throws InstallException {
		try {
			startInstall();		// 프로그램 설치에 필요한 준비를 한다.
			copyFiles();		// 파일들을 복사한다. 
		} catch (SpaceException e)	{
			InstallException ie = new InstallException("설치중 예외발생");
			ie.initCause(e);
			throw ie;
		} catch (MemoryException me) {
			InstallException ie = new InstallException("설치중 예외발생");
			ie.initCause(me);
			throw ie;
		} finally {
			deleteTempFiles();	// 프로그램 설치에 사용된 임시파일들을 삭제한다.
		} // try의 끝
	}

static void startInstall() throws SpaceException, MemoryException { 
	if(!enoughSpace()) { 		// 충분한 설치 공간이 없으면...
		throw new SpaceException("설치할 공간이 부족합니다.");
	}

	if (!enoughMemory()) {		// 충분한 메모리가 없으면...
		throw new MemoryException("메모리가 부족합니다.");
//		throw new RuntimeException(new MemoryException("메모리가 부족합니다."));
	}
} // startInstall메서드의 끝

   static void copyFiles() { /* 파일들을 복사하는 코드를 적는다. */ }
   static void deleteTempFiles() { /* 임시파일들을 삭제하는 코드를 적는다.*/}
   
   static boolean enoughSpace()   {
		// 설치하는데 필요한 공간이 있는지 확인하는 코드를 적는다.
		return false;
   }
   static boolean enoughMemory() {
		// 설치하는데 필요한 메모리공간이 있는지 확인하는 코드를 적는다.
		return true;
   }
} // ExceptionTest클래스의 끝

class InstallException extends Exception {
	InstallException(String msg) {
	   super(msg);	
   }
} 

class SpaceException extends Exception {
	SpaceException(String msg) {
	   super(msg);	
   }
} 

class MemoryException extends Exception {
	MemoryException(String msg) {
	   super(msg);	
   }
}

InstallException: 설치중 예외발생
    at Main.install(Main.java:17)
    at Main.main(Main.java:4)
Caused by: SpaceException: 설치할 공간이 부족합니다.
    at Main.startInstall(Main.java:31)
    at Main.install(Main.java:14)
    ... 1 more
```